Workbook

Sheet INSTRUCTIVO
B2: INSTRUCTIVO PARA EL DILEGENCIAMIENTO DEL FORMATO CARACTERIZACIÓN DE CIUDADANÍA Caracterización de CIUDADANÍA: Caracterizar es identificar las particularidades (características, necesidades, intereses, expectativas y preferencias) de los ciudadanos, usuarios o interesados con los cuales interactúa una entidad, con el fin de agruparlos según atributos o variables similares y, a partir de allí, gestionar acciones.
B3: Nota: La captura de la información se realizará a través del registro de datos solicitados en los items 01 al 15, que corresponde a los ciudadanos beneficiarios de los bienes y/o servicios brindados por la Gobernación de Casanare.
B4: CASILLA | C4: DESCRIPCION
C5: Favor diligenciar todo el formato en Arial 9, no utilice negrillas
B6: Nombres y Apellidos (1) | C6: Diligencie el nombre y apellidos completos.
B7: Tipo (2) | C7: Registre y/o seleccione de la lista deplegable el tipo de documento: CC: Cédula de Ciudadanía,TI: Tarjeta de Identidad, RC: Registro Civil, CE: Cédula de extranjería, Pasaporte.
B8: Número Documento de Identidad (3) | C8: Registre el numero de documento de identificación de la persona natural, sin puntos
B9: Área Urbana / Rural (4) | C9: Esta información es importante para la ubicación de ejecución de los proyectos a través de mapeo, como un sistema de información gráfico.
B10: Urbana | C10: Marque con una (X) si la ubicación de residencia es en el área Urbana.
B11: Rural | C11: Marque con una (X) si la ubicación de residencia es en el área Rural.
B12: Dirección- Barrio /Vereda y nombre del predio (5) | C12: Registre la dirección de residencia y el nombre del Barrio, o para el área rural el nombre de la vereda y el predio y/o finca del beneficiario.
B13: Municipio (6) | C13: Registre el Municipio donde esta ubicada la persona beneficiada del bien o servicio
B14: Teléfono/Celular / correo elec. (7) | C14: Registre el teléfono y/o celular, correo electrónico de la persona natural para contactar.
B15: ENFOQUE DE GÉNERO (8) | C15: Marque con una (X) si la persona natural es: F: Femenino, M: Masculino, NB: No Binario, o LGTBIQ+ ( L: Lesbianas, G: Gays, B: Bisexuales, T: Transexuales y Travestis,I: Intersexuales, Q: Queer, +: Colectivos no representados en las siglas ) Y LGBTIQ+ OSIGD
B16: ENFOQUE ÉTNICO (9) | C16: Marque con una (X) si la persona natural se auto determina como Indígena, Comunidad de raza negra raizales ó como Pueblo Rrom o Gitano.
B17: PROBLEMÁTICA A ATENDER (10) | C17: Marque con una (X) dentro de los sectores en lo que se presenta la problemática o acción a intervenir: - Institucional: vulnerabilidad institucional si la persona reporta ausencia de la presencia del Estado donde vive la persona. - Ambiental: vulnerabilidad ambiental si la persona reporta afectación en las condiciones ambientales de donde vive la persona. - Salud: vulnerabilidad institucional si la persona reporta imposibilidad de acceder a servicios de salud donde vive la persona. -Cultural: vulnerabilidad institucional si la persona reporta riesgos de perdida o desaparición de identidad cultural donde vive la persona. -Educativa: vulnerabilidad Educativa si la persona reporta imposibilidad de acceder a servicios de formación educativa formal donde vive la persona.
... B22: Lenguas, Idiomas o dialectos (15) | C22: Registre el Idioma, la Lengua o el Dialecto que la persona natural hable diferente al español. (En caso de que aplique)
B23: Nota: El registro de la información se realizará a partir de los items 16 al 28, que corresponde al seguimiento que realiza la persona responsable de los proyectos identificados en el formato FO-PDD-28, por las unidades ejecutoras de la Gobernación de Casanare.
B24: CODIGO DEPARTAMENTO Y MUNICIPIO (16) | C24: Seleccione el código del Municipio ejemplo: para Yopal 85001, donde esta ubicada la persona beneficiada del bien o servicio.
B25: BENEFICIO Y/O INTERES (17) | C25: De acuerdo a las categorias y bienes y/o servicios identificadas en la dependencia en el formato FO-PDD-28 Identificación de productos y servicios.
B26: CATEGORIA (17.1) | C26: Registre la categoria del Bien y/o servicio
B27: BIEN Y/O SERVICIO (17.2) | C27: Registre el Bien y/o servicio identificados en el formato FO-PDD-28
B28: DESCRIPCION BENEFICIO Y/O INTERES (18) | C28: Registre la Descripción del Bien y servicio si requiere un mayor detalle.
B29: FECHA DEL BENEFICIO Y/O INTERES (19) | C29: Registre la fecha en la que recibió el beneficio.
B30: GESTION/INVERSION (20) | C30: Registre si los recursos utilizador para atender esta necesidad fueron de Inversión o Gestión (Recursos gestionados con el sector privado u otros, que no requirió presupuesto de la administración.)
B31: GRUPOS ETÁREOS (21) | C31: El grupo etario se genera automáticamente mediante la formula de acuerdo a la edad registrada en el numeral 12. (Favor no diligenciar datos en esta columna, para no alterar la formula de cálculo de los grupos etarios). La clasificación en grupo etário según rango de edades: Primera infancia (De 0 a 5 años), Infancia (De 6 a 11), Adolescencia (De 12 a 17 años), Jóvenes (De 18 a 28 años) , Adultos ( 29 a 59 años) y Mayores (De 60 en adelante).
B32: PLAN DE DESARROLLO (22) | C32: Registre el sector del plan de desarrollo que impacte el Bien o servicio, o seleccione N/A
B33: SECTOR (22.1) | C33: Registre el Programa del plan de desarrollo que impacte el Biene o servicio, si no impacta seleccione N/A, escribalo igual a como se encuentra en el Plan de Desarrollo.
B34: PROGRAMA (22.2) | C34: Registre el la Meta Producto del plan de desarrollo que impacte el Biene o servicio, si no impacta seleccione N/A, escribalo igual a como se encuentre en el Plan de Desarrollo
B35: META PRODUCTO (22.3) | C35: Registre el nombre del Proyecto viabilizado en la Direccion de Banco de Proyectos, escriba el nombre completo del proyecto.
... B43: TOTAL DE BENEFICIARIOS (27) | C43: Registre la cantidad total de beneficiarios del proyecto.
B44: ACTO ADMINISTRATIVO DE EJECUCION DEL PROYECTO (28)
B45: TIPO (28.1) | C45: Registre el Acto administrativo de Ejecución del Proyecto: CTO- Contrato CV- Convenios CA- Carta de aceptacion RES-. Resolucion Incorpore otras columnas de este componente si la ejecución se realizó a través de más de un contrato o convenio.
B46: NUMERO (28.2) | C46: Registre el numero del Acto Administrativo
B47: Fecha (28.3) | C47: Registre fecha de suscripción del acto administrativo.
B49: Nota: La hojas denomidas ACTIVIDAD y PROYECTO, corresponden a instrumentos que permiten consolidar datos correspondientes a la población beneficiada con enfoque diferencial respecto de las actividades contractuales desarrolladas del proyecto de inversión que realiza la caracterización respectiva de acuerdo a la ejecución del Plan de Desarrollo Departamental. Esta información es insumo para el reporte de informes de gestión, rendición de cuentas entre otros, ya que se obtienen los datos consolidados por población beneficiada directa por meta.
B50: hoja: | C50: ACTIVIDAD
C51: En esta hoja se registra de acuerdo a lo diligenciado en la tabla 6 de Ciudadanos, el total de ciudadanos por actividad y por Municipios. En el encabeza se diligencia la meta de producto que se atiende de acuerdo al Plan de Desarrollo. Se consolidará lo de todos los contratos ejecutados del proyecto.
B55: hoja: | C55: PROYECTO
C56: En esta hoja se registra de acuerdo a lo diligenciado en la hoja de ACTIVIDAD, el total de población atendida por Municipio (se suman los total de las actividades de los contratos realizados con cargo al proyecto y por municipio), y en el encabezado se diligencia el nombre del proyecto que se ejecuta., se totaliza cada columna de informacion de enfoque de género, población vulnerable e identificando el ODS, DDHH o Pilares de paz que se atendieron con el proyecto, por municipio, Esta hoja es importante porque es el consolidado que se tendrá en cuenta para informar la gestión y avance a plan de desarrollo con los requerimientos de identificación poblacional, enfoque diferencia, y ODS, DDHH, Pilares de Paz y Políticas Públicas e Institucionales.

Sheet FO-PDD-19
A1: TEMA: | AI1: TIPO DE EVENTO | AJ1: SEGUIMIENTO CARACTERIZACION CIUDADANÍA
A2: FECHA: | N2: HORA: | AI2: Asistencia Técnica: | CA2: OBJETIVOS DE DESARROLLO SOSTENIBLE | CB2: DERECHOS HUMANOS | CC2: PILARES DE PAZ | CD2: POLITICAS PUBLICAS | CE2: POLITICAS DE MIPG
A3: QUIEN DIRIGE Y/O EXPONE: FIRMA: MUNICIPIO: | O3: DEPARTAMENTO: | AI3: Capacitación: | CA3: 1. Fin de la pobreza. | CB3: 1. Todos los seres humanos nacen libres e iguales. | CC3: 1. Lucha contra el crimen organizado. | CD3: PP. Discapacidad e inclusión social. | CE3: Planeación Institucional
A4: La Gobernación de Casanare en cumplimiento de la Ley 1581 de 2012 , el Decreto reglamentario 1377 de 2013 referente a Protección de Datos Personales, los datos aquí consignados serán tratados mediante el uso y mantenimiento de seguridad técnicas, físicas y administrativas a fin de impedir que terceros no autorizados accedan a los mismos. L: Lesbianas, G: Gays,B: Bisexuales,T: Transexuales,I: Intersexuales, Q: Queer-+: Colectivos no representados en las siglas, PPL: Personas Privadas de la Libertad, -TD: Número de identificación Personas Privadas de la Libertad PPR: Personas en Proceso de Reintegración Y LGBTIQ+ OSIGD | AI4: Socialización: Otro: | CA4: 2. Hambre cero | CB4: 2. Todas las personas tienen los derechos proclamados en esta carta. | CC4: 2. Apoyo al proceso de paz | CD4: PP. Primera infancia, Infancia, Adolescencia. | CE4: Gestión presupuestal y eficiencia del gasto público
A5: N° | B5: Nombres y Apellidos y/o Nombre de la Entidad u Organización Social (1) | C5: Tipo Documento(2) | D5: Número Documento de Identidad y/o NIT (3) | E5: Cargo (4) Barrio /Vereda | F5: Municipio (5) | G5: ZONA Urbana / Rural (6) | I5: Ubicación (7) Dirección/ nombre del predio | J5: Número de Contacto (8) | K5: ENFOQUE DE GÉNERO (9) | P5: ENFOQUE ÉTNICO (10) | S5: PROBLEMÁTICA A ATENDER (11) | X5: SECTOR De La ORGANIZACIÓN (12) | Y5: CLASIFICACIÓN DE LA ORGANIZACIÓN (13) | AA5: ENFOQUE DIFERENCIAL/POBLACIONAL (14) | AE5: EDAD - grupo etário (15) | AF5: Tamaño Grupo Familiar (16) | AG5: Canal de Comunicación (17) | AH5: Idiomas, Lenguas o dialectos (18) | AI5: FIRMA (19) | AJ5: CODIGO DEPARTAMENTO / MUNICIPIO (20) | AK5: BENEFICIO Y/O INTERES (21) | AM5: DESCRIPCION BENEFICIO Y/O INTERES (22) | AN5: FECHA DEL BENEFICIO Y/O INTERES (23) (dd/mm/aa) | AO5: GESTION/INVERSION (24) | AP5: GRUPOS ETÁREOS (25) | AQ5: PLAN DE DESARROLLO DEPARTAMENTAL VIGENTE (26) | AT5: NOMBRE DEL PROYECTO DE INVERSION (27) | AU5: EJECUCIÓN CLASIFICADA POR ODS, DDHH, PILARES DE PAZ (28) | AX5: POLITICA PÚBLICA A LA QUE APLICA (29) | AY5: POLITICA INSTITUCIONAL DE MIPG (30) | AZ5: TOTAL DE BENEFICIARIOS (31) | BA5: ACTO ADMINISTRATIVO DE EJECUCION DEL PROYECTO (32) | BX5: IDIOMA | CA5: 3. Salud y Bienestar | CB5: 3. Todo individuo tiene derecho a la vida, la libertad y la seguridad. | CC5: 3. Desarrollo Rural | CD5: PP. De Juventud. | CE5: Gestión del Talento Humano
K6: Mujer Hombre No Binario | O6: LGBTIQ+ OSIGD | P6: Indígenas | Q6: Comun. Negras - Afro- Raizales - Palenqueras | R6: Pueblo Rom o Gitano | S6: Institucional | T6: Ambiental | U6: Salud | V6: Cultural | W6: Educativa | Y6: Con Animo de Lucro | Z6: Sin Animo de Lucro | AA6: Discapacidad | AB6: Cabeza de Hogar | AC6: Víctimas de Conflicto | AD6: Habitante de la calle | AK6: CATEGORIA (21.1) | AL6: BIEN Y/O SERVICIO (21.2) | AQ6: SECTOR (26.1) | AR6: PROGRAMA (26.2) | AS6: META PRODUCTO (26.3) | AU6: OBJETIVOS DE DESARROLLO SOSTENIBLE (28.1) | AV6: DDHH (28.2) | AW6: PILARES DE PAZ (28.3) | BA6: TIPO (32.1) | BB6: NUMERO (32.2) | BC6: Fecha (32.3) (dd/mm/aa) | BQ6: C.C | BR6: Presidente | BS6: AGUAZUL | BT6: Barrio | BU6: Teléfono | BV6: 1 | BW6: Radio | BX6: Aleman | BY6: Entidad Territorial | BZ6: CON ÁNIMO DE LUCRO | CA6: 4. Educación de Calidad | CB6: 4. Nadie será sometido a esclavitud ni a servidumbre. | CC6: 4. Erradicación de minas antipersonas | CD6: PP. Para la Gestión de la salud mental y la prevención del consumo de Drogas. | CE6: Integridad
G7: U | H7: R | K7: F | L7: M | M7: NB | N7: T | BQ7: T.I | BR7: Gerente | BS7: CHAMEZA | BT7: Centro Poblado | BU7: Celular | BV7: 2 | BW7: Página Web | BX7: Inglés | BY7: Sector Educativo | BZ7: SIN ÁNIMO DE LUCRO | CA7: 5. Igualdad de Género | CB7: 5. Nadie será sometido a penas, torturas ni tratos crueles o inhumanos. | CC7: N/A | CD7: PP. NAL. De Equidad de Género | CE7: Transparencia, acceso a la información pública y lucha contra la corrupción
AP8: =+IF(AE8=0," ",IF(AE8<=5,"Primera infancia",IF(AE8<=11,"Infancia",IF(AE8<=17,"Adolescencia",IF(AE8<=28,"Jóvenes",IF(AE8<=60,"Adultos",IF(AE8<=120,"Mayores",""))))))) | BQ8: R.C | BR8: SubGerente | BS8: HATO COROZAL | BT8: Comuna | BV8: 3 | BW8: Redes Sociales | BX8: Francés | BY8: Sector Salud | CA8: 6. Agua limpia y saneamiento | CB8: 6. Todo ser humano tiene derecho al reconocimiento de su personalidad jurídica. | CD8: PP. Equidad de género para las mujeres de Casanare. | CE8: Fortalecimiento Organizacional y simplificación de procesos
AP9: =+IF(AE9=0," ",IF(AE9<=5,"Primera infancia",IF(AE9<=11,"Infancia",IF(AE9<=17,"Adolescencia",IF(AE9<=28,"Jóvenes",IF(AE9<=60,"Adultos",IF(AE9<=120,"Mayores",""))))))) | BQ9: C.E | BS9: LA SALINA | BT9: Corregimiento | BV9: 4 | BW9: Juntas de Acción Comunal | BX9: Portugués | BY9: Sector Recreación y Deporte | CA9: 7. Energía asequible y no contaminante. | CB9: 7. Todos tienen derecho a la protección contra la discriminación. | CD9: PP Envejecimiento y Vejez. | CE9: Servicio al Ciudadano (solución a las necesidades de la comunidad)
AP10: =+IF(AE10=0," ",IF(AE10<=5,"Primera infancia",IF(AE10<=11,"Infancia",IF(AE10<=17,"Adolescencia",IF(AE10<=28,"Jóvenes",IF(AE10<=60,"Adultos",IF(AE10<=120,"Mayores",""))))))) | BQ10: PASAPORTE | BS10: MANI | BT10: Inspección de Policía | BV10: 5 | BX10: Italiano | BY10: Sector Gobierno | CA10: 8. trabajo decente y crecimiento económico | CB10: 8. Toda persona tiene derecho a un recurso efectivo ante los tribunales. | CD10: PP. Comunal | CE10: Participación ciudadana en la Gestión Pública
AP11: =+IF(AE11=0," ",IF(AE11<=5,"Primera infancia",IF(AE11<=11,"Infancia",IF(AE11<=17,"Adolescencia",IF(AE11<=28,"Jóvenes",IF(AE11<=60,"Adultos",IF(AE11<=120,"Mayores",""))))))) | BQ11: NIT | BS11: MONTERREY | BT11: Localidad | BV11: 6 | BX11: Mandarin | CA11: 9. Industria, innovación e infraestructura. | CB11: 9. Nadie podrá ser detenido, desterrado ni preso arbitrariamente. | CD11: PP. Libertad Religiosa, de Culto y Conciencia. | CE11: Racionalización de trámites
AP12: =+IF(AE12=0," ",IF(AE12<=5,"Primera infancia",IF(AE12<=11,"Infancia",IF(AE12<=17,"Adolescencia",IF(AE12<=28,"Jóvenes",IF(AE12<=60,"Adultos",IF(AE12<=120,"Mayores",""))))))) | BS12: NUNCHIA | BT12: Vereda | BV12: 7 | BX12: Japonés | CA12: 10. Reducción de las desigualdades. | CB12: 10. Toda persona tiene derecho a un tribunal independiente e imparcial. | CD12: PP. NAL. De Víctimas del conflicto armado. | CE12: Gestión Documental
AP13: =+IF(AE13=0," ",IF(AE13<=5,"Primera infancia",IF(AE13<=11,"Infancia",IF(AE13<=17,"Adolescencia",IF(AE13<=28,"Jóvenes",IF(AE13<=60,"Adultos",IF(AE13<=120,"Mayores",""))))))) | BS13: OROCUE | BT13: Finca | BV13: 8 | BX13: LENGUA | CA13: 11. Ciudades y Comunidades sostenibles. | CB13: 11. Toda persona tiene derecho a la presunción de inocencia y a penas justas. | CD13: PP. NAL. Garantía del goce efectivo de los Derechos de las personas LGTBI. | CE13: Gobierno digital
AP14: =+IF(AE14=0," ",IF(AE14<=5,"Primera infancia",IF(AE14<=11,"Infancia",IF(AE14<=17,"Adolescencia",IF(AE14<=28,"Jóvenes",IF(AE14<=60,"Adultos",IF(AE14<=120,"Mayores",""))))))) | BS14: PAZ DE ARIPORO | BT14: Nombre del Predio | BV14: 9 | BX14: Lengua de Señas - LSC | CA14: 12. Producción y consumo responsables. | CB14: 12. Toda persona tiene derecho a la privacidad, la honra y la reputación. | CD14: POL. NAL. De Reintegración social y económica para personas y grupos armados ilegales. | CE14: Seguridad Digital
AP15: =+IF(AE15=0," ",IF(AE15<=5,"Primera infancia",IF(AE15<=11,"Infancia",IF(AE15<=17,"Adolescencia",IF(AE15<=28,"Jóvenes",IF(AE15<=60,"Adultos",IF(AE15<=120,"Mayores",""))))))) | BS15: PORE | BV15: 10 | BX15: Achagua | CA15: 13. Acción por el clima. | CB15: 13. Toda persona tiene derecho a la libre circulación y a elegir libremente su residencia. | CD15: N/A | CE15: Gestión del Conocimiento y la Innovación
AP16: =+IF(AE16=0," ",IF(AE16<=5,"Primera infancia",IF(AE16<=11,"Infancia",IF(AE16<=17,"Adolescencia",IF(AE16<=28,"Jóvenes",IF(AE16<=60,"Adultos",IF(AE16<=120,"Mayores",""))))))) | BS16: RECETOR | BV16: 11 | BX16: Amorua | CA16: 14. Vida Submarina. | CB16: 14. Toda persona tiene derecho al asilo en cualquier país. | CE16: Seguimiento y evaluación del desempeño institucional
AP17: =+IF(AE17=0," ",IF(AE17<=5,"Primera infancia",IF(AE17<=11,"Infancia",IF(AE17<=17,"Adolescencia",IF(AE17<=28,"Jóvenes",IF(AE17<=60,"Adultos",IF(AE17<=120,"Mayores",""))))))) | BS17: SABANALARGA | BV17: 12 | BX17: Andoke | CA17: 15. Vida de Ecosistemas terrestres. | CB17: 15. Toda persona tiene derecho a una nacionalidad y a cambiar de nacionalidad. | CE17: Control Interno
AP18: =+IF(AE18=0," ",IF(AE18<=5,"Primera infancia",IF(AE18<=11,"Infancia",IF(AE18<=17,"Adolescencia",IF(AE18<=28,"Jóvenes",IF(AE18<=60,"Adultos",IF(AE18<=120,"Mayores",""))))))) | BS18: SACAMA | BX18: Awapit | CA18: 16. Paz, justicia e instituciones sólidas. | CB18: 16. Todos los individuos tienen derecho a un matrimonio libre y a la protección de la familia. | CE18: Mejora normativa
AP19: =+IF(AE19=0," ",IF(AE19<=5,"Primera infancia",IF(AE19<=11,"Infancia",IF(AE19<=17,"Adolescencia",IF(AE19<=28,"Jóvenes",IF(AE19<=60,"Adultos",IF(AE19<=120,"Mayores",""))))))) | BS19: SAN LUIS DE PALENQUE | BX19: Baniva | CA19: 17. Alianzas para lograr los objetivos. | CB19: 17. Toda persona tiene derecho a la propiedad individual o colectiva. | CE19: Gestión de la Información Estadística
AP20: =+IF(AE20=0," ",IF(AE20<=5,"Primera infancia",IF(AE20<=11,"Infancia",IF(AE20<=17,"Adolescencia",IF(AE20<=28,"Jóvenes",IF(AE20<=60,"Adultos",IF(AE20<=120,"Mayores",""))))))) | BS20: TAMARA | BX20: Bara | CA20: N/A | CB20: 18. Toda persona tiene derecho a la libertad de pensamiento, conciencia y religión. | CE20: Compras y contratación pública
AP21: =+IF(AE21=0," ",IF(AE21<=5,"Primera infancia",IF(AE21<=11,"Infancia",IF(AE21<=17,"Adolescencia",IF(AE21<=28,"Jóvenes",IF(AE21<=60,"Adultos",IF(AE21<=120,"Mayores",""))))))) | BS21: TAURAMENA | BX21: Barasano | CB21: 19. Todo individuo tiene derecho a la libertad de opinión y de expresión. | CE21: Defensa Juridica
AP22: =+IF(AE22=0," ",IF(AE22<=5,"Primera infancia",IF(AE22<=11,"Infancia",IF(AE22<=17,"Adolescencia",IF(AE22<=28,"Jóvenes",IF(AE22<=60,"Adultos",IF(AE22<=120,"Mayores",""))))))) | BS22: TRINIDAD | BX22: Bari | CB22: 20. Toda persona tiene derecho a la libertad de reunión y asociación. | CE22: N/A
AP23: =+IF(AE23=0," ",IF(AE23<=5,"Primera infancia",IF(AE23<=11,"Infancia",IF(AE23<=17,"Adolescencia",IF(AE23<=28,"Jóvenes",IF(AE23<=60,"Adultos",IF(AE23<=120,"Mayores",""))))))) | BS23: VILLANUEVA | BX23: Betoye-guahibo | CB23: 21. Toda persona tiene derecho a participar, directa o indirectamente, en el gobierno de su país.
AP24: =+IF(AE24=0," ",IF(AE24<=5,"Primera infancia",IF(AE24<=11,"Infancia",IF(AE24<=17,"Adolescencia",IF(AE24<=28,"Jóvenes",IF(AE24<=60,"Adultos",IF(AE24<=120,"Mayores",""))))))) | BS24: YOPAL | BX24: Bora | CB24: 22. Toda persona tiene derecho a la seguridad social.
AP25: =+IF(AE25=0," ",IF(AE25<=5,"Primera infancia",IF(AE25<=11,"Infancia",IF(AE25<=17,"Adolescencia",IF(AE25<=28,"Jóvenes",IF(AE25<=60,"Adultos",IF(AE25<=120,"Mayores",""))))))) | BX25: Cabiyari | CB25: 23. Toda persona tiene derecho al trabajo y la protección contra el desempleo.
AP26: =+IF(AE26=0," ",IF(AE26<=5,"Primera infancia",IF(AE26<=11,"Infancia",IF(AE26<=17,"Adolescencia",IF(AE26<=28,"Jóvenes",IF(AE26<=60,"Adultos",IF(AE26<=120,"Mayores",""))))))) | BX26: Carapana | CB26: 24. Toda persona tiene derecho al descanso y al disfrute del tiempo libre.
AP27: =+IF(AE27=0," ",IF(AE27<=5,"Primera infancia",IF(AE27<=11,"Infancia",IF(AE27<=17,"Adolescencia",IF(AE27<=28,"Jóvenes",IF(AE27<=60,"Adultos",IF(AE27<=120,"Mayores",""))))))) | BX27: Cocama | CB27: 25. Toda persona tiene derecho al bienestar: alimentación, vivienda, asistencia médica, vestido y otros servicios sociales básicos.
AP28: =+IF(AE28=0," ",IF(AE28<=5,"Primera infancia",IF(AE28<=11,"Infancia",IF(AE28<=17,"Adolescencia",IF(AE28<=28,"Jóvenes",IF(AE28<=60,"Adultos",IF(AE28<=120,"Mayores",""))))))) | BX28: Cubeo | CB28: 26. Toda persona tiene derecho a la educación y al libre desarrollo de la personalidad.
AP29: =+IF(AE29=0," ",IF(AE29<=5,"Primera infancia",IF(AE29<=11,"Infancia",IF(AE29<=17,"Adolescencia",IF(AE29<=28,"Jóvenes",IF(AE29<=60,"Adultos",IF(AE29<=120,"Mayores",""))))))) | BX29: Curripaco | CB29: 27. Toda persona tiene derecho a tomar parte en la vida cultural de su comunidad.
AP30: =+IF(AE30=0," ",IF(AE30<=5,"Primera infancia",IF(AE30<=11,"Infancia",IF(AE30<=17,"Adolescencia",IF(AE30<=28,"Jóvenes",IF(AE30<=60,"Adultos",IF(AE30<=120,"Mayores",""))))))) | BX30: Damana | CB30: 28. Toda persona tiene derecho a un orden social que garantice los derechos de esta carta.
AP31: =+IF(AE31=0," ",IF(AE31<=5,"Primera infancia",IF(AE31<=11,"Infancia",IF(AE31<=17,"Adolescencia",IF(AE31<=28,"Jóvenes",IF(AE31<=60,"Adultos",IF(AE31<=120,"Mayores",""))))))) | BX31: Desano | CB31: 29. Toda persona tiene deberes con respecto a su comunidad.
AP32: =+IF(AE32=0," ",IF(AE32<=5,"Primera infancia",IF(AE32<=11,"Infancia",IF(AE32<=17,"Adolescencia",IF(AE32<=28,"Jóvenes",IF(AE32<=60,"Adultos",IF(AE32<=120,"Mayores",""))))))) | BX32: Embera | CB32: No aplica
AP33: =+IF(AE33=0," ",IF(AE33<=5,"Primera infancia",IF(AE33<=11,"Infancia",IF(AE33<=17,"Adolescencia",IF(AE33<=28,"Jóvenes",IF(AE33<=60,"Adultos",IF(AE33<=120,"Mayores",""))))))) | BX33: Embera chami
AP34: =+IF(AE34=0," ",IF(AE34<=5,"Primera infancia",IF(AE34<=11,"Infancia",IF(AE34<=17,"Adolescencia",IF(AE34<=28,"Jóvenes",IF(AE34<=60,"Adultos",IF(AE34<=120,"Mayores",""))))))) | BX34: Embera dovida
AP35: =+IF(AE35=0," ",IF(AE35<=5,"Primera infancia",IF(AE35<=11,"Infancia",IF(AE35<=17,"Adolescencia",IF(AE35<=28,"Jóvenes",IF(AE35<=60,"Adultos",IF(AE35<=120,"Mayores",""))))))) | BX35: Embera katio
AP36: =+IF(AE36=0," ",IF(AE36<=5,"Primera infancia",IF(AE36<=11,"Infancia",IF(AE36<=17,"Adolescencia",IF(AE36<=28,"Jóvenes",IF(AE36<=60,"Adultos",IF(AE36<=120,"Mayores",""))))))) | BX36: Eperara siapidara
AP37: =+IF(AE37=0," ",IF(AE37<=5,"Primera infancia",IF(AE37<=11,"Infancia",IF(AE37<=17,"Adolescencia",IF(AE37<=28,"Jóvenes",IF(AE37<=60,"Adultos",IF(AE37<=120,"Mayores",""))))))) | BX37: Ette taara
AP38: =+IF(AE38=0," ",IF(AE38<=5,"Primera infancia",IF(AE38<=11,"Infancia",IF(AE38<=17,"Adolescencia",IF(AE38<=28,"Jóvenes",IF(AE38<=60,"Adultos",IF(AE38<=120,"Mayores",""))))))) | BX38: Guahibo
AP39: =+IF(AE39=0," ",IF(AE39<=5,"Primera infancia",IF(AE39<=11,"Infancia",IF(AE39<=17,"Adolescencia",IF(AE39<=28,"Jóvenes",IF(AE39<=60,"Adultos",IF(AE39<=120,"Mayores",""))))))) | BX39: Guna dule
AP40: =+IF(AE40=0," ",IF(AE40<=5,"Primera infancia",IF(AE40<=11,"Infancia",IF(AE40<=17,"Adolescencia",IF(AE40<=28,"Jóvenes",IF(AE40<=60,"Adultos",IF(AE40<=120,"Mayores",""))))))) | BX40: Hitnu (macaguan)
...

Sheet ACTIVIDAD 
A1: INSTRUMENTO PARA CONSOLIDAR LOS DATOS CORRESPONDIENTES A LA POBLACIÓN BENEFICIADA CON ENFOQUE DIFERENCIAL DE LAS ACTIVIDADES CONTRACTUALES DESARROLLADAS Y SU CARACTERIZACIÓN RESPECTIVA
A3: POBLACIÓN BENEFICIADA DIRECTA: Se registrará la información de la población que de manera directa fue beneficiada por la ejecución de cada una de las actividades desarrolladas para el cumplimiento de la Meta de Producto.
B5: NOMBRE DE LA META PRODUCTO | E5: xxxxxx
A7: N° | B7: Actividad Contractual | C7: ODS / DD HH / ACUERDO DE PAZ | D7: Municipio | E7: Área Urbana /Rural | G7: ENFOQUE DE GÉNERO | L7: ENFOQUE ÉTNICO | O7: SECTOR De La ORGANIZACIÓN | P7: CLASIFICACIÓN DE LA ORGANIZACIÓN | R7: ENFOQUE DIFERENCIAL / POBLACIONAL | V7: GRUPOS ETAREOS | AB7: TOTAL POBLACIÓN ATENDIDA
G8: Mujer Hombre No Binario | K8: LGBTIQ+ OSIGD | L8: Indígenas | M8: Comun. Negras - Afro- Raizales - Palenqueras | N8: Pueblo Rom o Gitano | P8: Con Animo de Lucro | Q8: Sin Animo de Lucro | R8: Discapacidad | S8: Cabeza de Hogar | T8: Víctimas de Conflicto | U8: Habitante de la calle | V8: Primera infancia 0-5 años | W8: Infancia 6 a 11 años | X8: Adolescencia 12 a 17 años | Y8: Jóvenes 18 a 28 años | Z8: Adulto 29-60 | AA8: Mayores de 61 años
E9: U | F9: R | G9: F | H9: M | I9: NB | J9: T
A10: 1 | D10: Aguazul | E10: 0 | F10: 5 | G10: 3 | H10: 2 | L10: 5 | V10: 3 | Y10: 2 | AB10: =SUM(E10:AA10) -> 20
A11: 2 | D11: Aguazul | E11: 0 | F11: 7 | G11: 5 | H11: 2 | L11: 7 | W11: 5 | X11: 2 | AB11: =SUM(V11:AA11) -> 7
A12: 3 | D12: Aguazul | AB12: =SUM(E12:AA12) -> 0
A13: 4 | D13: Aguazul | AB13: =SUM(E13:AA13) -> 0
D14: Total Aguazul | E14: =SUM(E10:E13) -> 0 | F14: =SUM(F10:F13) -> 12 | G14: =SUM(G10:G13) -> 8 | H14: =SUM(H10:H13) -> 4 | I14: =SUM(I10:I13) -> 0 | J14: =SUM(J10:J13) -> 0 | K14: =SUM(K10:K13) -> 0 | L14: =SUM(L10:L13) -> 12 | ... AB14: =SUM(AB10:AB13) -> 27 | AZ14: =SUBTOTAL(9,AZ10:AZ13) -> 0
A15: 1 | D15: Chámeza | AB15: =SUM(E15:AA15) -> 0
A16: 2 | D16: Chámeza | AB16: =SUM(E16:AA16) -> 0
A17: 3 | D17: Chámeza | E17: 5 | F17: 5 | G17: 5 | H17: 5 | K17: 5 | AB17: =SUM(E17:AA17) -> 25
A18: 4 | D18: Chámeza | AB18: =SUM(E18:AA18) -> 0
D19: Total Chámeza | E19: =SUM(E15:E18) -> 5 | F19: =SUM(F15:F18) -> 5 | G19: =SUM(G15:G18) -> 5 | H19: =SUM(H15:H18) -> 5 | K19: =SUM(K15:K18) -> 5 | L19: =SUM(L15:L18) -> 0 | M19: =SUM(M15:M18) -> 0 | N19: =SUM(N15:N18) -> 0 | R19: =SUM(R15:R18) -> 0 | S19: =SUM(S15:S18) -> 0 | T19: =SUM(T15:T18) -> 0 | U19: =SUM(U15:U18) -> 0 | V19: =SUM(V15:V18) -> 0 | W19: =SUM(W15:W18) -> 0 | X19: =SUM(X15:X18) -> 0 | Y19: =SUM(Y15:Y18) -> 0 | ... AB19: =SUM(AB15:AB18) -> 25 | AZ19: =SUBTOTAL(9,AZ15:AZ18) -> 0
A20: 1 | D20: Hato Corozal | AB20: =SUM(E20:AA20) -> 0
A21: 2 | D21: Hato Corozal | AB21: =SUM(E21:AA21) -> 0
A22: 3 | D22: Hato Corozal | Z22: 5 | AB22: =SUM(E22:AA22) -> 5
A23: 4 | D23: Hato Corozal | AB23: =SUM(E23:AA23) -> 0
D24: Total Hato Corozal | E24: =SUBTOTAL(9,E20:E23) -> 0 | F24: =SUBTOTAL(9,F20:F23) -> 0 | G24: =SUBTOTAL(9,G20:G23) -> 0 | H24: =SUBTOTAL(9,H20:H23) -> 0 | I24: =SUBTOTAL(9,I20:I23) -> 0 | J24: =SUBTOTAL(9,J20:J23) -> 0 | K24: =SUBTOTAL(9,K20:K23) -> 0 | L24: =SUBTOTAL(9,L20:L23) -> 0 | ... AB24: =SUBTOTAL(9,AB20:AB23) -> 5 | AZ24: =SUBTOTAL(9,AZ20:AZ23) -> 0
A25: 1 | D25: La Salina | AB25: =SUM(E25:AA25) -> 0
A26: 2 | D26: La Salina | AB26: =SUM(E26:AA26) -> 0
A27: 3 | D27: La Salina | AB27: =SUM(E27:AA27) -> 0
A28: 4 | D28: La Salina | AB28: =SUM(E28:AA28) -> 0
D29: Total La Salina | E29: =SUBTOTAL(9,E25:E28) -> 0 | F29: =SUBTOTAL(9,F25:F28) -> 0 | G29: =SUBTOTAL(9,G25:G28) -> 0 | H29: =SUBTOTAL(9,H25:H28) -> 0 | I29: =SUBTOTAL(9,I25:I28) -> 0 | J29: =SUBTOTAL(9,J25:J28) -> 0 | K29: =SUBTOTAL(9,K25:K28) -> 0 | L29: =SUBTOTAL(9,L25:L28) -> 0 | ... AB29: =SUBTOTAL(9,AB25:AB28) -> 0 | AZ29: =SUBTOTAL(9,AZ25:AZ28) -> 0
A30: 1 | D30: Maní | AB30: =SUM(E30:AA30) -> 0
A31: 2 | D31: Maní | AB31: =SUM(E31:AA31) -> 0
A32: 3 | D32: Maní | AB32: =SUM(E32:AA32) -> 0
A33: 4 | D33: Maní | E33: 5 | AA33: 3 | AB33: =SUM(E33:AA33) -> 8
D34: Total Maní | E34: =SUBTOTAL(9,E30:E33) -> 5 | F34: =SUBTOTAL(9,F30:F33) -> 0 | G34: =SUBTOTAL(9,G30:G33) -> 0 | H34: =SUBTOTAL(9,H30:H33) -> 0 | I34: =SUBTOTAL(9,I30:I33) -> 0 | J34: =SUBTOTAL(9,J30:J33) -> 0 | K34: =SUBTOTAL(9,K30:K33) -> 0 | L34: =SUBTOTAL(9,L30:L33) -> 0 | ... AB34: =SUBTOTAL(9,AB30:AB33) -> 8 | AZ34: =SUBTOTAL(9,AZ30:AZ33) -> 0
A35: 1 | D35: Monterrey | AB35: =SUM(E35:AA35) -> 0
A36: 2 | D36: Monterrey | AB36: =SUM(E36:AA36) -> 0
A37: 3 | D37: Monterrey | W37: 5 | AB37: =SUM(E37:AA37) -> 5
A38: 4 | D38: Monterrey | AB38: =SUM(E38:AA38) -> 0
D39: Total Monterrey | E39: =SUBTOTAL(9,E35:E38) -> 0 | F39: =SUBTOTAL(9,F35:F38) -> 0 | G39: =SUBTOTAL(9,G35:G38) -> 0 | H39: =SUBTOTAL(9,H35:H38) -> 0 | I39: =SUBTOTAL(9,I35:I38) -> 0 | J39: =SUBTOTAL(9,J35:J38) -> 0 | K39: =SUBTOTAL(9,K35:K38) -> 0 | L39: =SUBTOTAL(9,L35:L38) -> 0 | ... AB39: =SUBTOTAL(9,AB35:AB38) -> 5 | AZ39: =SUBTOTAL(9,AZ35:AZ38) -> 0
A40: 1 | D40: Nunchía | AB40: =SUM(E40:AA40) -> 0
A41: 2 | D41: Nunchía | AB41: =SUM(E41:AA41) -> 0
A42: 3 | D42: Nunchía | AB42: =SUM(E42:AA42) -> 0
A43: 4 | D43: Nunchía | W43: 5 | AB43: =SUM(E43:AA43) -> 5
...

Sheet PROYECTO
A1: INSTRUMENTO PARA CONSOLIDAR LOS DATOS CORRESPONDIENTES A LA POBLACIÓN BENEFICIADA CON ENFOQUE DIFERENCIAL DE LAS ACTIVIDADES CONTRACTUALES DESARROLLADAS Y SU CARACTERIZACIÓN RESPECTIVA
A3: POBLACIÓN BENEFICIADA DIRECTA: Se registrará la información de la población que de manera directa fue beneficiada por la ejecución de cada uno de los proyectos desarrollados para el cumplimiento de las Metas de Producto.
B5: PROYECTO
A7: N° | B7: Municipio | C7: Área Urbana /Rural | E7: ENFOQUE DE GÉNERO | J7: ENFOQUE ÉTNICO | M7: SECTOR De La ORGANIZACIÓN | N7: CLASIFICACIÓN DE LA ORGANIZACIÓN | P7: ENFOQUE DIFERENCIAL/POBLACIONAL | T7: GRUPOS ETAREOS | Z7: TOTAL POBLACIÓN ATENDIDA
E8: Mujer Hombre No Binario | I8: LGBTIQ+ OSIGD | J8: Indígenas | K8: Comun. Negras - Afro- Raizales - Palenqueras | L8: Pueblo Rom o Gitano | N8: Con Animo de Lucro | O8: Sin Animo de Lucro | P8: Discapacidad | Q8: Cabeza de Hogar | R8: Víctimas de Conflicto | S8: Habitante de la calle | T8: Primera infancia 0-5 años | U8: Infancia 6 a 11 años | V8: Adolescencia 12 a 17 años | W8: Jóvenes 18 a 28 años | X8: Adulto 29-60 | Y8: Mayores de 61 años
C9: U | D9: R | E9: F | F9: M | G9: NB | H9: T
A10: 1 | B10: Aguazul | C10: =+'ACTIVIDAD '!E14 -> 0 | D10: =+'ACTIVIDAD '!F14 -> 12 | E10: =+'ACTIVIDAD '!G14 -> 8 | F10: =+'ACTIVIDAD '!H14 -> 4 | G10: =+'ACTIVIDAD '!I14 -> 0 | H10: =+'ACTIVIDAD '!J14 -> 0 | I10: =+'ACTIVIDAD '!K14 -> 0 | J10: =+'ACTIVIDAD '!L14 -> 12 | ... Y10: =+'ACTIVIDAD '!AA14 -> 0 | Z10: =SUM(C10:Y10) -> 48
A11: 2 | B11: Chámeza | C11: =+'ACTIVIDAD '!E19 -> 5 | D11: =+'ACTIVIDAD '!F19 -> 5 | E11: =+'ACTIVIDAD '!G19 -> 5 | F11: =+'ACTIVIDAD '!H19 -> 5 | G11: =+'ACTIVIDAD '!I19 -> 0 | H11: =+'ACTIVIDAD '!J19 -> 0 | I11: =+'ACTIVIDAD '!K19 -> 5 | J11: =+'ACTIVIDAD '!L19 -> 0 | ... Y11: =+'ACTIVIDAD '!AA19 -> 0 | Z11: =SUM(C11:Y11) -> 25
A12: 3 | B12: Hato Corozal | C12: =+'ACTIVIDAD '!E24 -> 0 | D12: =+'ACTIVIDAD '!F24 -> 0 | E12: =+'ACTIVIDAD '!G24 -> 0 | F12: =+'ACTIVIDAD '!H24 -> 0 | G12: =+'ACTIVIDAD '!I24 -> 0 | H12: =+'ACTIVIDAD '!J24 -> 0 | I12: =+'ACTIVIDAD '!K24 -> 0 | J12: =+'ACTIVIDAD '!L24 -> 0 | ... Y12: =+'ACTIVIDAD '!AA24 -> 0 | Z12: =SUM(C12:Y12) -> 5
A13: 4 | B13: La Salina | C13: =+'ACTIVIDAD '!E29 -> 0 | D13: =+'ACTIVIDAD '!F29 -> 0 | E13: =+'ACTIVIDAD '!G29 -> 0 | F13: =+'ACTIVIDAD '!H29 -> 0 | G13: =+'ACTIVIDAD '!I29 -> 0 | H13: =+'ACTIVIDAD '!J29 -> 0 | I13: =+'ACTIVIDAD '!K29 -> 0 | J13: =+'ACTIVIDAD '!L29 -> 0 | ... Y13: =+'ACTIVIDAD '!AA29 -> 0 | Z13: =SUM(C13:Y13) -> 0
A14: 5 | B14: Maní | C14: =+'ACTIVIDAD '!E34 -> 5 | D14: =+'ACTIVIDAD '!F34 -> 0 | E14: =+'ACTIVIDAD '!G34 -> 0 | F14: =+'ACTIVIDAD '!H34 -> 0 | G14: =+'ACTIVIDAD '!I34 -> 0 | H14: =+'ACTIVIDAD '!J34 -> 0 | I14: =+'ACTIVIDAD '!K34 -> 0 | J14: =+'ACTIVIDAD '!L34 -> 0 | ... Y14: =+'ACTIVIDAD '!AA34 -> 3 | Z14: =SUM(C14:Y14) -> 8
A15: 6 | B15: Monterrey | C15: =+'ACTIVIDAD '!E39 -> 0 | D15: =+'ACTIVIDAD '!F39 -> 0 | E15: =+'ACTIVIDAD '!G39 -> 0 | F15: =+'ACTIVIDAD '!H39 -> 0 | G15: =+'ACTIVIDAD '!I39 -> 0 | H15: =+'ACTIVIDAD '!J39 -> 0 | I15: =+'ACTIVIDAD '!K39 -> 0 | J15: =+'ACTIVIDAD '!L39 -> 0 | ... Y15: =+'ACTIVIDAD '!AA39 -> 0 | Z15: =SUM(C15:Y15) -> 5
A16: 7 | B16: Nunchía | C16: =+'ACTIVIDAD '!E44 -> 0 | D16: =+'ACTIVIDAD '!F44 -> 0 | E16: =+'ACTIVIDAD '!G44 -> 0 | F16: =+'ACTIVIDAD '!H44 -> 0 | G16: =+'ACTIVIDAD '!I44 -> 0 | H16: =+'ACTIVIDAD '!J44 -> 0 | I16: =+'ACTIVIDAD '!K44 -> 0 | J16: =+'ACTIVIDAD '!L44 -> 0 | ... Y16: =+'ACTIVIDAD '!AA44 -> 0 | Z16: =SUM(C16:Y16) -> 5
A17: 8 | B17: Orocué | C17: =+'ACTIVIDAD '!E49 -> 0 | D17: =+'ACTIVIDAD '!F49 -> 0 | E17: =+'ACTIVIDAD '!G49 -> 0 | F17: =+'ACTIVIDAD '!H49 -> 0 | G17: =+'ACTIVIDAD '!I49 -> 0 | H17: =+'ACTIVIDAD '!J49 -> 0 | I17: =+'ACTIVIDAD '!K49 -> 0 | J17: =+'ACTIVIDAD '!L49 -> 0 | ... Y17: =+'ACTIVIDAD '!AA49 -> 0 | Z17: =SUM(C17:Y17) -> 5
A18: 9 | B18: Paz de Ariporo | C18: =+'ACTIVIDAD '!E54 -> 0 | D18: =+'ACTIVIDAD '!F54 -> 0 | E18: =+'ACTIVIDAD '!G54 -> 0 | F18: =+'ACTIVIDAD '!H54 -> 0 | G18: =+'ACTIVIDAD '!I54 -> 0 | H18: =+'ACTIVIDAD '!J54 -> 0 | I18: =+'ACTIVIDAD '!K54 -> 0 | J18: =+'ACTIVIDAD '!L54 -> 0 | ... Y18: =+'ACTIVIDAD '!AA54 -> 0 | Z18: =SUM(C18:Y18) -> 0
A19: 10 | B19: Pore | C19: =+'ACTIVIDAD '!E59 -> 0 | D19: =+'ACTIVIDAD '!F59 -> 0 | E19: =+'ACTIVIDAD '!G59 -> 0 | F19: =+'ACTIVIDAD '!H59 -> 0 | G19: =+'ACTIVIDAD '!I59 -> 0 | H19: =+'ACTIVIDAD '!J59 -> 0 | I19: =+'ACTIVIDAD '!K59 -> 0 | J19: =+'ACTIVIDAD '!L59 -> 0 | ... Y19: =+'ACTIVIDAD '!AA59 -> 0 | Z19: =SUM(C19:Y19) -> 0
A20: 11 | B20: Recetor | C20: =+'ACTIVIDAD '!E64 -> 0 | D20: =+'ACTIVIDAD '!F64 -> 0 | E20: =+'ACTIVIDAD '!G64 -> 0 | F20: =+'ACTIVIDAD '!H64 -> 0 | G20: =+'ACTIVIDAD '!I64 -> 0 | H20: =+'ACTIVIDAD '!J64 -> 0 | I20: =+'ACTIVIDAD '!K64 -> 0 | J20: =+'ACTIVIDAD '!L64 -> 0 | ... Y20: =+'ACTIVIDAD '!AA64 -> 0 | Z20: =SUM(C20:Y20) -> 0
A21: 12 | B21: Sabanalarga | C21: =+'ACTIVIDAD '!E69 -> 0 | D21: =+'ACTIVIDAD '!F69 -> 0 | E21: =+'ACTIVIDAD '!G69 -> 0 | F21: =+'ACTIVIDAD '!H69 -> 0 | G21: =+'ACTIVIDAD '!I69 -> 0 | H21: =+'ACTIVIDAD '!J69 -> 0 | I21: =+'ACTIVIDAD '!K69 -> 0 | J21: =+'ACTIVIDAD '!L69 -> 0 | ... Y21: =+'ACTIVIDAD '!AA69 -> 0 | Z21: =SUM(C21:Y21) -> 0
A22: 13 | B22: Sácama | C22: =+'ACTIVIDAD '!E74 -> 0 | D22: =+'ACTIVIDAD '!F74 -> 0 | E22: =+'ACTIVIDAD '!G74 -> 0 | F22: =+'ACTIVIDAD '!H74 -> 0 | G22: =+'ACTIVIDAD '!I74 -> 0 | H22: =+'ACTIVIDAD '!J74 -> 0 | I22: =+'ACTIVIDAD '!K74 -> 0 | J22: =+'ACTIVIDAD '!L74 -> 0 | ... Y22: =+'ACTIVIDAD '!AA74 -> 0 | Z22: =SUM(C22:Y22) -> 0
A23: 14 | B23: San Luis de Palenque | C23: =+'ACTIVIDAD '!E79 -> 0 | D23: =+'ACTIVIDAD '!F79 -> 0 | E23: =+'ACTIVIDAD '!G79 -> 0 | F23: =+'ACTIVIDAD '!H79 -> 0 | G23: =+'ACTIVIDAD '!I79 -> 0 | H23: =+'ACTIVIDAD '!J79 -> 0 | I23: =+'ACTIVIDAD '!K79 -> 0 | J23: =+'ACTIVIDAD '!L79 -> 0 | ... Y23: =+'ACTIVIDAD '!AA79 -> 0 | Z23: =SUM(C23:Y23) -> 0
A24: 15 | B24: Támara | C24: =+'ACTIVIDAD '!E84 -> 3 | D24: =+'ACTIVIDAD '!F84 -> 7 | E24: =+'ACTIVIDAD '!G84 -> 8 | F24: =+'ACTIVIDAD '!H84 -> 0 | G24: =+'ACTIVIDAD '!I84 -> 0 | H24: =+'ACTIVIDAD '!J84 -> 0 | I24: =+'ACTIVIDAD '!K84 -> 0 | J24: =+'ACTIVIDAD '!L84 -> 0 | ... Y24: =+'ACTIVIDAD '!AA84 -> 0 | Z24: =SUM(C24:Y24) -> 18
A25: 16 | B25: Tauramena | C25: =+'ACTIVIDAD '!E89 -> 0 | D25: =+'ACTIVIDAD '!F89 -> 0 | E25: =+'ACTIVIDAD '!G89 -> 0 | F25: =+'ACTIVIDAD '!H89 -> 0 | G25: =+'ACTIVIDAD '!I89 -> 0 | H25: =+'ACTIVIDAD '!J89 -> 0 | I25: =+'ACTIVIDAD '!K89 -> 0 | J25: =+'ACTIVIDAD '!L89 -> 0 | ... Y25: =+'ACTIVIDAD '!AA89 -> 0 | Z25: =SUM(C25:Y25) -> 0
A26: 17 | B26: Trinidad | C26: =+'ACTIVIDAD '!E94 -> 0 | D26: =+'ACTIVIDAD '!F94 -> 0 | E26: =+'ACTIVIDAD '!G94 -> 0 | F26: =+'ACTIVIDAD '!H94 -> 0 | G26: =+'ACTIVIDAD '!I94 -> 0 | H26: =+'ACTIVIDAD '!J94 -> 0 | I26: =+'ACTIVIDAD '!K94 -> 0 | J26: =+'ACTIVIDAD '!L94 -> 0 | ... Y26: =+'ACTIVIDAD '!AA94 -> 0 | Z26: =SUM(C26:Y26) -> 0
A27: 18 | B27: Villanueva | C27: =+'ACTIVIDAD '!E99 -> 0 | D27: =+'ACTIVIDAD '!F99 -> 0 | E27: =+'ACTIVIDAD '!G99 -> 0 | F27: =+'ACTIVIDAD '!H99 -> 0 | G27: =+'ACTIVIDAD '!I99 -> 0 | H27: =+'ACTIVIDAD '!J99 -> 0 | I27: =+'ACTIVIDAD '!K99 -> 0 | J27: =+'ACTIVIDAD '!L99 -> 0 | ... Y27: =+'ACTIVIDAD '!AA99 -> 0 | Z27: =SUM(C27:Y27) -> 0
A28: 19 | B28: Yopal | C28: =+'ACTIVIDAD '!E104 -> 0 | D28: =+'ACTIVIDAD '!F104 -> 0 | E28: =+'ACTIVIDAD '!G104 -> 0 | F28: =+'ACTIVIDAD '!H104 -> 0 | G28: =+'ACTIVIDAD '!I104 -> 0 | H28: =+'ACTIVIDAD '!J104 -> 0 | I28: =+'ACTIVIDAD '!K104 -> 0 | J28: =+'ACTIVIDAD '!L104 -> 0 | ... Y28: =+'ACTIVIDAD '!AA104 -> 0 | Z28: =SUM(C28:Y28) -> 0
A29: TOTAL GENERAL | C29: =SUM(C10:C28) -> 13 | D29: =SUM(D10:D28) -> 24 | E29: =SUM(E10:E28) -> 21 | F29: =SUM(F10:F28) -> 9 | G29: =SUM(G10:G28) -> 0 | H29: =SUM(H10:H28) -> 0 | I29: =SUM(I10:I28) -> 5 | J29: =SUM(J10:J28) -> 12 | ... Z29: =SUM(Z10:Z28) -> 119
H32: VERIFICACIÓN DE DATOS - POR FAVOR NO BORRAR | R32: =SUM(C29:D29) -> 37 | T32: =SUM(E29:G29) -> 30
G34: FECHA ÚLTIMA ACTUALIZACIÓN DE LA INFORMACIÓN:
C1043558: Estado de la solicitud
C1043559: Seleccione
C1043560: Finalizada
C1043561: En trámite
